project_id: 0, data_type: tempC, value: 25
project_id: 0, data_type: tempC, value: 35
project_id: 0, data_type: tempC, value: 35
project_id: 0, data_type: tempC, value: 25
project_id: 0, data_type: tempC, value: 27
project_id: 0, data_type: tempC, value: 29
project_id: 0, data_type: tempC, value: 29
Exception on /scratchx [POST]
Traceback (most recent call last):
  File "/home/marc/.local/lib/python3.5/site-packages/flask/app.py", line 1982, in wsgi_app
    response = self.full_dispatch_request()
  File "/home/marc/.local/lib/python3.5/site-packages/flask/app.py", line 1614, in full_dispatch_request
    rv = self.handle_user_exception(e)
  File "/usr/local/lib/python3.5/dist-packages/flask_cors/extension.py", line 161, in wrapped_function
    return cors_after_request(app.make_response(f(*args, **kwargs)))
  File "/home/marc/.local/lib/python3.5/site-packages/flask/app.py", line 1517, in handle_user_exception
    reraise(exc_type, exc_value, tb)
  File "/home/marc/.local/lib/python3.5/site-packages/flask/_compat.py", line 33, in reraise
    raise value
  File "/home/marc/.local/lib/python3.5/site-packages/flask/app.py", line 1612, in full_dispatch_request
    rv = self.dispatch_request()
  File "/home/marc/.local/lib/python3.5/site-packages/flask/app.py", line 1598, in dispatch_request
    return self.view_functions[rule.endpoint](**req.view_args)
  File "/home/marc/Documentos/WMSI/website/linode-resources/flask/app/routes.py", line 202, in scratchx
    emit('new value', {'data': 'new_val'})
  File "/usr/local/lib/python3.5/dist-packages/flask_socketio/__init__.py", line 688, in emit
    namespace = flask.request.namespace
  File "/home/marc/.local/lib/python3.5/site-packages/werkzeug/local.py", line 347, in __getattr__
    return getattr(self._get_current_object(), name)
AttributeError: 'Request' object has no attribute 'namespace'
project_id: 0, data_type: tempC, value: 29
Exception on /scratchx [POST]
Traceback (most recent call last):
  File "/home/marc/.local/lib/python3.5/site-packages/flask/app.py", line 1982, in wsgi_app
    response = self.full_dispatch_request()
  File "/home/marc/.local/lib/python3.5/site-packages/flask/app.py", line 1614, in full_dispatch_request
    rv = self.handle_user_exception(e)
  File "/usr/local/lib/python3.5/dist-packages/flask_cors/extension.py", line 161, in wrapped_function
    return cors_after_request(app.make_response(f(*args, **kwargs)))
  File "/home/marc/.local/lib/python3.5/site-packages/flask/app.py", line 1517, in handle_user_exception
    reraise(exc_type, exc_value, tb)
  File "/home/marc/.local/lib/python3.5/site-packages/flask/_compat.py", line 33, in reraise
    raise value
  File "/home/marc/.local/lib/python3.5/site-packages/flask/app.py", line 1612, in full_dispatch_request
    rv = self.dispatch_request()
  File "/home/marc/.local/lib/python3.5/site-packages/flask/app.py", line 1598, in dispatch_request
    return self.view_functions[rule.endpoint](**req.view_args)
  File "/home/marc/Documentos/WMSI/website/linode-resources/flask/app/routes.py", line 202, in scratchx
    emit('new value', {'data': 'new_val'})
  File "/usr/local/lib/python3.5/dist-packages/flask_socketio/__init__.py", line 688, in emit
    namespace = flask.request.namespace
  File "/home/marc/.local/lib/python3.5/site-packages/werkzeug/local.py", line 347, in __getattr__
    return getattr(self._get_current_object(), name)
AttributeError: 'Request' object has no attribute 'namespace'
project_id: 0, data_type: tempC, value: 29
Exception on /scratchx [POST]
Traceback (most recent call last):
  File "/home/marc/.local/lib/python3.5/site-packages/flask/app.py", line 1982, in wsgi_app
    response = self.full_dispatch_request()
  File "/home/marc/.local/lib/python3.5/site-packages/flask/app.py", line 1614, in full_dispatch_request
    rv = self.handle_user_exception(e)
  File "/usr/local/lib/python3.5/dist-packages/flask_cors/extension.py", line 161, in wrapped_function
    return cors_after_request(app.make_response(f(*args, **kwargs)))
  File "/home/marc/.local/lib/python3.5/site-packages/flask/app.py", line 1517, in handle_user_exception
    reraise(exc_type, exc_value, tb)
  File "/home/marc/.local/lib/python3.5/site-packages/flask/_compat.py", line 33, in reraise
    raise value
  File "/home/marc/.local/lib/python3.5/site-packages/flask/app.py", line 1612, in full_dispatch_request
    rv = self.dispatch_request()
  File "/home/marc/.local/lib/python3.5/site-packages/flask/app.py", line 1598, in dispatch_request
    return self.view_functions[rule.endpoint](**req.view_args)
  File "/home/marc/Documentos/WMSI/website/linode-resources/flask/app/routes.py", line 202, in scratchx
    send('new value') # , {'data': 'new_val'})
  File "/usr/local/lib/python3.5/dist-packages/flask_socketio/__init__.py", line 738, in send
    namespace = flask.request.namespace
  File "/home/marc/.local/lib/python3.5/site-packages/werkzeug/local.py", line 347, in __getattr__
    return getattr(self._get_current_object(), name)
AttributeError: 'Request' object has no attribute 'namespace'
project_id: 0, data_type: tempC, value: 29
Exception on /scratchx [POST]
Traceback (most recent call last):
  File "/home/marc/.local/lib/python3.5/site-packages/flask/app.py", line 1982, in wsgi_app
    response = self.full_dispatch_request()
  File "/home/marc/.local/lib/python3.5/site-packages/flask/app.py", line 1614, in full_dispatch_request
    rv = self.handle_user_exception(e)
  File "/usr/local/lib/python3.5/dist-packages/flask_cors/extension.py", line 161, in wrapped_function
    return cors_after_request(app.make_response(f(*args, **kwargs)))
  File "/home/marc/.local/lib/python3.5/site-packages/flask/app.py", line 1517, in handle_user_exception
    reraise(exc_type, exc_value, tb)
  File "/home/marc/.local/lib/python3.5/site-packages/flask/_compat.py", line 33, in reraise
    raise value
  File "/home/marc/.local/lib/python3.5/site-packages/flask/app.py", line 1612, in full_dispatch_request
    rv = self.dispatch_request()
  File "/home/marc/.local/lib/python3.5/site-packages/flask/app.py", line 1598, in dispatch_request
    return self.view_functions[rule.endpoint](**req.view_args)
  File "/home/marc/Documentos/WMSI/website/linode-resources/flask/app/routes.py", line 202, in scratchx
    send('new value', namespace='/update') # , {'data': 'new_val'})
  File "/usr/local/lib/python3.5/dist-packages/flask_socketio/__init__.py", line 743, in send
    room = flask.request.sid
  File "/home/marc/.local/lib/python3.5/site-packages/werkzeug/local.py", line 347, in __getattr__
    return getattr(self._get_current_object(), name)
AttributeError: 'Request' object has no attribute 'sid'
project_id: 0, data_type: tempC, value: 29
project_id: 0, data_type: tempC, value: 29
project_id: 0, data_type: tempC, value: 29
sending new value
sending new value
project_id: 0, data_type: tempC, value: 29
project_id: 0, data_type: tempC, value: 29
project_id: 0, data_type: tempC, value: 29
Exception on /scratchx [POST]
Traceback (most recent call last):
  File "/home/marc/.local/lib/python3.5/site-packages/flask/app.py", line 1982, in wsgi_app
    response = self.full_dispatch_request()
  File "/home/marc/.local/lib/python3.5/site-packages/flask/app.py", line 1614, in full_dispatch_request
    rv = self.handle_user_exception(e)
  File "/usr/local/lib/python3.5/dist-packages/flask_cors/extension.py", line 161, in wrapped_function
    return cors_after_request(app.make_response(f(*args, **kwargs)))
  File "/home/marc/.local/lib/python3.5/site-packages/flask/app.py", line 1517, in handle_user_exception
    reraise(exc_type, exc_value, tb)
  File "/home/marc/.local/lib/python3.5/site-packages/flask/_compat.py", line 33, in reraise
    raise value
  File "/home/marc/.local/lib/python3.5/site-packages/flask/app.py", line 1612, in full_dispatch_request
    rv = self.dispatch_request()
  File "/home/marc/.local/lib/python3.5/site-packages/flask/app.py", line 1598, in dispatch_request
    return self.view_functions[rule.endpoint](**req.view_args)
  File "/home/marc/Documentos/WMSI/website/linode-resources/flask/app/routes.py", line 202, in scratchx
    send_new_value(data);
  File "/home/marc/Documentos/WMSI/website/linode-resources/flask/app/routes.py", line 258, in send_new_value
    socketio.emit('new value', data)
  File "/usr/local/lib/python3.5/dist-packages/flask_socketio/__init__.py", line 373, in emit
    skip_sid=skip_sid, callback=callback, **kwargs)
  File "/usr/local/lib/python3.5/dist-packages/socketio/server.py", line 228, in emit
    **kwargs)
  File "/usr/local/lib/python3.5/dist-packages/socketio/base_manager.py", line 135, in emit
    self.server._emit_internal(sid, event, data, namespace, id)
  File "/usr/local/lib/python3.5/dist-packages/socketio/server.py", line 403, in _emit_internal
    binary=binary))
  File "/usr/local/lib/python3.5/dist-packages/socketio/server.py", line 407, in _send_packet
    encoded_packet = pkt.encode()
  File "/usr/local/lib/python3.5/dist-packages/socketio/packet.py", line 71, in encode
    encoded_packet += self.json.dumps(data, separators=(',', ':'))
  File "/usr/lib/python3.5/json/__init__.py", line 237, in dumps
    **kw).encode(obj)
  File "/usr/lib/python3.5/json/encoder.py", line 198, in encode
    chunks = self.iterencode(o, _one_shot=True)
  File "/usr/lib/python3.5/json/encoder.py", line 256, in iterencode
    return _iterencode(o, 0)
  File "/usr/lib/python3.5/json/encoder.py", line 179, in default
    raise TypeError(repr(o) + " is not JSON serializable")
TypeError: <DataStory 0, 2018-05-27 19:32:34.676123> is not JSON serializable
project_id: 0, data_type: tempC, value: 29
project_id: 0, data_type: tempC, value: 29
project_id: 0, data_type: tempC, value: 29
project_id: 0, data_type: tempC, value: 30
project_id: 0, data_type: tempC, value: 30
project_id: 0, data_type: tempC, value: 31
project_id: 0, data_type: tempC, value: 32
project_id: 0, data_type: tempC, value: 22
